Workbook

Sheet Marketing Starter Kit
A1: 📝 | B1: Marketing Starter Kit | C1: Status | D1: Difficulty | E1: Impact
A3: STEP 1 | B3: Create your marketing strategy
B4: Create a buyer persona | C4: Not Started | D4: Hard | E4: High
B5: Enrich your personas | C5: Not Started | D5: Medium | E5: High
B6: Create your digital marketing strategy | C6: Not Started | D6: Hard | E6: High
B7: Prioritize your funnel initiatives | C7: Not Started | D7: Hard | E7: Medium
A9: STEP 2 | B9: Kickstart your SEO engine
B10: Find your website's most important pages for SEO | C10: Not Started | D10: Medium | E10: High
B11: Perform an SEO audit on your most important pages | C11: Not Started | D11: Hard | E11: Medium
B12: Optimize your most important pages | C12: Not Started | D12: Hard | E12: High
A14: STEP 3 | B14: Kickstart your social media engine
B15: Audit your social media accounts | C15: Not Started | D15: Medium | E15: Medium
B16: Create great content for social media | C16: Not Started | D16: Hard | E16: High
B17: Starting a social media calendar | C17: Not Started | D17: Medium | E17: Medium
B18: Create amazing social media content | C18: Not Started | D18: Hard | E18: High
A20: STEP 4 | B20: Kickstart your content engine
B21: Copy proven content templates to generate traffic | C21: Not Started | D21: Easy | E21: High
B22: Create engaging and effective content with AI | C22: Not Started | D22: Easy | E22: High
A24: STEP 5 | B24: Kickstart your email engine
B25: Reverse-engineer a competitor's email marketing strategy | C25: Not Started | D25: Hard | E25: High
B26: Implement email automation templates that drive sales | C26: Not Started | D26: Medium | E26: High
B27: Create high-converting email content | C27: Not Started | D27: Hard | E27: High
A29: STEP 6 | B29: Kickstart your paid ads engine
B30: Reverse engineer your competitor's Facebook Ads Strategy | C30: Not Started | D30: Medium | E30: High
B31: Reverse engineer your competitor's Google Ads Strategy | C31: Not Started | D31: Hard | E31: High
B32: Create high-converting ads | C32: Not Started | D32: Hard | E32: High

Sheet Link Building Checklist - SEO B
C1: The Link Building Checklist
A4: Finding Link Building Opportunities
B5: Main Checklist | C5: Resources
B6: Find backlink opportunities using an SEO tool like Semrush | C6: https://www.semrush.com/blog/find-backlinks/
B7: Check competitors’ content and find the sites linking to them | C7: https://userp.io/find-competitor-backlinks/
B8: Reclaim broken competitor links by providing your updated links | C8: https://ahrefs.com/blog/fix-broken-links/
B9: Get backlinks for any unlinked mentions for your brand | C9: https://www.searchenginejournal.com/link-building-guide/unlinked-brand-mentions/
B10: Make a list of guest posting sites in your niche and pitch to them | C10: https://bloggerspassion.com/guest-posting-sites-list/
B11: Find all relevant directories and get listings/citations | C11: https://www.searchenginejournal.com/citations-local-seo-guide/347380/
B12: Start an affiliate marketing program to build backlinks | C12: https://www.searchenginejournal.com/link-building-guide/affiliate/
A13: Vetting the Websites for Link Building
B14: Main Checklist
B15: Check the site’s domain authority score | C15: https://moz.com/learn/seo/domain-authority
B16: Make sure that it is a relevant site within your niche | C16: https://www.searchenginejournal.com/find-related-sites/9086/
B17: Ensure that the site is not on any blacklists | C17: https://geekflare.com/find-remove-blacklist-site/
B18: Read the site’s content to make sure it’s:
B19: ---- Relevant to your audience | C19: https://contentmarketinginstitute.com/2015/10/content-strategy-questions-answered/
B20: ---- High quality | C20: https://www.searchenginejournal.com/how-to-create-high-quality-content/254511/
B21: ---- Not spammy | C21: https://neilpatel.com/blog/spammers-and-negative-seo/
B22: Ensure that it is not a link farm | C22: https://www.rogeracuna.com/wordpress/site-link-farm/ https://www.rosemontmedia.com/surgeons-blog/industry-jargon-explained-link-farms/
B23: Check if they allow guest posts | C23: https://seo-hacker.com/find-sites-guest-blogging/
B24: Prefer sites that have a high organic search traffic | C24: https://www.incomediary.com/how-much-traffic-website-gets/
A25: Creating Content for Link Building - Basic Checklist for Creating Link Building Content
B26: Main Checklist
B27: Select topics according to the website | C27: https://neilpatel.com/blog/how-to-come-up-with-blog-ideas/ https://www.semrush.com/blog/how-to-find-blog-post-ideas/
B28: Meet the target site content guidelines | C28: https://www.semrush.com/blog/14-tips-for-writing-awesome-website-content/ https://blog.alexa.com/the-complete-guide-how-to-write-content-for-a-website/
B29: Use a relevant anchor text to add your link | C29: https://www.semrush.com/blog/what-is-anchor-text-and-how-can-i-optimize-it/
B30: Create unique, plagiarism-free content | C30: https://www.webdew.com/blog/content-writing-tips
B31: Add some internal links to the target site as a nice gesture | C31: https://neilpatel.com/blog/the-complete-guide-to-internal-linking/
B32: Add other contextual external links so that yours doesn’t stand out | C32: https://postaga.com/contextual-links/
B33: Place the link towards the top of the content and not the bottom | C33: https://uplandsoftware.com/kapost/resources/blog/link-strategy-blog-posts/
A34: Creating Content for Link Building - Types of Content You Can Create for Link Building
B35: Main Checklist
B36: Articles for guest posting | C36: https://blog.alexa.com/guest-posting/
B37: Infographics that can be distributed to multiple sites | C37: https://visme.co/blog/how-to-build-links-with-infographics/
B38: Research studies that many sites would want to cite | C38: https://blog.hubspot.com/marketing/case-studies-marketing
B39: Quora answers to industry-related questions | C39: https://neilpatel.com/blog/blog-quora-marketing-guide/
B40: HARO answers and expert quotes for roundups | C40: https://www.elegantthemes.com/blog/marketing/a-guide-to-haro-for-content-creators-and-marketers
A41: Assessing the Quality of Backlinks
B42: Main Checklist
...

Sheet Brand Information
B2: Foundational Network
B4: Brand Information
A5: 1 | B5: Website | C5: https://www.vitalmobility.ca/
A6: 3 | B6: Company Owner | C6: Bruno Rzeznikieiwiz
A7: 4 | B7: Business Name | C7: Vital Mobility
A8: 5 | B8: Address Line 1 | C8: 130 Bass Pro Mills Drive #62, Concord, ON L4K 5X2
A9: 6 | B9: City | C9: Concord
A10: 7 | B10: Province/State | C10: ON
A11: 8 | B11: Zip Code | C11: 94518
A12: 9 | B12: Phone (local) | C12: (905) 532-9494
A13: 10 | B13: Additional Business Information
A14: 11 | B14: Hours of operation | D14: Friday | E14: 9: 00am-5:00pm
A15: 12 | B15: Year Founded | C15: 39800 | D15: Saturday | E15: 10:00am-2:00pm
A16: 13 | B16: Headline/Tagline | C16: Vital Mobility | Medical Equipment Toronto | Medical Supply Toronto | Wheelchair Rental | D16: Sunday | E16: Closed
A17: 14 | B17: Business Description (minimum 400 characters) | C17: Introducing Vital Mobility Home Health Care Toronto, your premier source for hospital bed rentals, mobility scooter rentals, lift chairs rentals, and wheelchair rental. Elevate your comfort and independence—explore our top-notch rental solutions today! | D17: Monday | E17: 9: 00am-5:00pm
A18: 15 | B18: Payment Types Accepted | C18: All | D18: Tuesday | E18: 9: 00am-5:00pm
A19: 16 | B19: Contractor #/License # | C19: They dont have one - Business license they do | D19: Wednesday | E19: 9: 00am-5:00pm
A20: 17 | B20: Keyword #1 | C20: Hospital bed rentals | D20: Thursday | E20: 9: 00am-5:00pm
A21: 18 | B21: Keyword #2 | C21: hospital bed
A22: 19 | B22: Keyword #3 | C22: mobility scooter
A23: 20 | B23: Keyword #4 | C23: lift chairs,wheel chair rental
A24: 22 | B24: Company Logo: | C24: https://www.vitalmobility.ca/blog/wp-content/uploads/2016/01/vital-logo-new-pdf.pdf-2115.608-x-600-mm-1.png | D24: I will add the transparent logo too
A25: 23 | B25: Image 1 | C25: https://www.vitalmobility.ca/blog/wp-content/uploads/2024/01/IMG_6270.jpg | D25: Front store - Toronto / North York Store
A26: 24 | B26: Image 2 | C26: https://www.vitalmobility.ca/blog/wp-content/uploads/2024/01/IMG_6260.jpg | D26: Delivery Van
A27: 25 | B27: Image 3 | C27: https://www.vitalmobility.ca/blog/wp-content/uploads/2024/01/IMG_6266.jpg | D27: Home Hospital Beds
B28: Image 4 | C28: https://www.vitalmobility.ca/blog/wp-content/uploads/2024/01/IMG_6267.jpg | D28: Mobility Scooters
B29: Image 5 | C29: https://www.vitalmobility.ca/blog/wp-content/uploads/2024/01/IMG_3123.jpg | D29: Concord / Vaughan Store
A30: 26 | B30: Existing Account Information | C30: No
A31: 27 | B31: Any notes or special instructions for us? | C31: No

Sheet Social Essential Network
A1: Social Essential Network
A4: Website
B5: Email Address | C5: Password | D5: Recovery Email | E5: Phone #
A6: Gmail
A7: Social Accounts | B7: Profile URL | C7: Username | D7: Password | E7: Email | F7: Notes
A8: Blogger | B8: https://vitalmobility.blogspot.com/2023/12/rolling-freedom-unlocking-adventures.html | C8: Vital mobility | D8: auto login | E8: seo@thespeedtrain.com
A9: Gravatar | B9: https://gravatar.com/seo7e35dc32c2c8 | C9: Vital Mobility | D9: auto login | E9: seo@thespeedtrain.com
A10: Pinterest | B10: https://pin.it/7clqTjlXc | C10: Vital Mobility | D10: auto login | E10: seo@thespeedtrain.com
A11: Tumblr | B11: https://www.tumblr.com/vitalmobality/740879303765557248/vital-mobility-medical-equipment-toronto?source=share | C11: vitalmobality | E11: seo@thespeedtrain.com | F11: open with vpn
A12: Wordpress | B12: https://vitalmobility9.wordpress.com/2024/01/16/vital-mobility/ | C12: Vital Mobility | D12: auto login | E12: seo@thespeedtrain.com
A13: Youtube | B13: https://www.youtube.com/@vitalmobility | C13: Vital Mobility | D13: auto login | E13: seo@thespeedtrain.com
A14: Coub.com | B14: https://coub.com/vitalmobility1 | C14: Vital Mobility | D14: vital321 | E14: seo@thespeedtrain.com
A15: Buzzfeed | B15: https://www.buzzfeed.com/oldskull68/vital-mobility-desp82vjo5?utm_source=dynamic&utm_campaign=bfsharecopy | C15: Vital Mobility | D15: auto login | E15: seo@thespeedtrain.com
A16: Diigo | B16: https://diigo.com/0v2dxc | C16: Vital Mobility | D16: vital321 | E16: seo@thespeedtrain.com
A17: Disqus | B17: https://disqus.com/by/vital_mobility/about/ | C17: Vital Mobility | D17: auto login | E17: seo@thespeedtrain.com
A18: Medium | B18: https://medium.com/@vitalmobility | C18: Vital Mobility | D18: auto login | E18: seo@thespeedtrain.com
A19: Minds.com | B19: https://www.minds.com/vitalmobility/ | C19: Vital Mobility | D19: @Vital321 | E19: seo@thespeedtrain.com
A20: Quora | B20: https://www.quora.com/profile/Vital-Mobility-2 | C20: Vital Mobility | D20: auto login | E20: seo@thespeedtrain.com
A21: Facebook | B21: https://www.facebook.com/VitalMobility/ | C21: Vital Mobility | D21: vital321 | E21: seo@thespeedtrain.com
A22: Wikidot | B22: https://www.wikidot.com/user:info/vital-mobility | C22: Vital Mobility | D22: vital321 | E22: seo@thespeedtrain.com
A23: Issuu | B23: https://issuu.com/vitalmobility1 | C23: Vital Mobility | D23: vital321 | E23: seo@thespeedtrain.com
... A26: fliphtml5 | B26: https://fliphtml5.com/homepage/xqvhf/seo-thespeedtrain/ | C26: Vital Mobility | D26: auto login | E26: seo@thespeedtrain.com

Sheet Social Fortress Upgrade
A1: Social Fortress Upgrade
A3: Website
B4: Email Address | C4: Password | D4: Recovery Email | E4: Phone #
A5: Gmail
A6: Social Accounts | B6: Profile URL | C6: Username | D6: Password | E6: Email | F6: Notes
A7: pearltrees | B7: https://www.pearltrees.com/vitalmobility1 | C7: Vital Mobility | D7: vital321 | E7: seo@thespeedtrain.com
A8: bloglovin | B8: https://www.bloglovin.com/@vitalmobality | C8: Vital Mobility | D8: vital321 | E8: seo@thespeedtrain.com
A9: blurb | B9: https://www.blurb.com/user/vitalmobilit?profile_preview=true | C9: Vital Mobility | D9: vital321 | E9: seo@thespeedtrain.com
A10: instapaper | B10: https://www.instapaper.com/p/13597872 | C10: Vital Mobility | D10: vital321 | E10: seo@thespeedtrain.com
A11: penzu | B11: https://penzu.com/p/10c35e3622b84d13 | C11: Vital Mobility | D11: vital321 | E11: seo@thespeedtrain.com
A12: https://letterboxd.com/ | B12: https://letterboxd.com/vitalmobility1/ | C12: Vital Mobility | D12: vital321 | E12: seo@thespeedtrain.com
A13: https://www.goodreads.com/ | B13: https://www.goodreads.com/user/show/174515392-vitalmobility | C13: Vital Mobility | D13: vital321 | E13: seo@thespeedtrain.com
A14: https://triberr.com/ | B14: https://triberr.com/vitalmobility1 | C14: Vital Mobility | D14: vital321 | E14: seo@thespeedtrain.com
A15: https://sketchfab.com/ | B15: https://sketchfab.com/vitalmobility1 | C15: Vital Mobility | D15: vital321 | E15: seo@thespeedtrain.com
A16: https://slides.com/ | B16: https://slides.com/vitalmobility2 | C16: Vital Mobility | D16: auto login | E16: seo@thespeedtrain.com
A17: https://www.atlasobscura.com/ | B17: https://www.atlasobscura.com/users/vitalmobility2 | C17: Vital Mobility | D17: auto login | E17: seo@thespeedtrain.com
A18: https://substack.com/ | B18: https://substack.com/@vitalmobility | C18: Vital Mobility | D18: auto login | E18: seo@thespeedtrain.com
... A27: https://peatix.com/ | B27: https://peatix.com/user/20696729/view | C27: Vital Mobility | D27: auto login | E27: seo@thespeedtrain.com

Sheet Social Ultimate Upgrade
A1: Social Ultimate Upgrade
A3: Website
B4: Email Address | C4: Password | D4: Recovery Email | E4: Phone #
A5: Gmail
A6: Social Accounts | B6: Profile URL | C6: Username | D6: Password | E6: Email | F6: Notes
A7: magcloud | B7: https://www.magcloud.com/user/vitalmobility1 | C7: vitalmobility1 | D7: vital321 | E7: seo@thespeedtrain.com
A8: ted | B8: https://www.ted.com/profiles/45982849 | C8: vital mobility | D8: auto login | E8: seo@thespeedtrain.com
A9: 4shared | B9: https://www.4shared.com/u/Cud894R4/seo.html | C9: vital mobility | D9: auto login | E9: seo@thespeedtrain.com
A10: All4webs.com | B10: https://all4webs.com/vitalmobility1/home.htm?11157=13652 | C10: vital mobility | D10: vital321 | E10: seo@thespeedtrain.com
A11: giphy.com | B11: https://giphy.com/channel/vitalmobility1 | C11: vital mobility | D11: auto login | E11: seo@thespeedtrain.com
A12: https://padlet.com/ | B12: https://padlet.com/vitalmobility/my-fearless-padlet-ufq3jpn1hzcivktg | C12: vital mobility | D12: auto login | E12: seo@thespeedtrain.com
A13: behance | B13: https://www.behance.net/gallery/189706147/Vital-Mobility | C13: vital mobility | D13: auto login | E13: seo@thespeedtrain.com
A14: kickstarter | B14: https://www.kickstarter.com/profile/vitalmobility/about | C14: vital mobility | D14: vital321 | E14: seo@thespeedtrain.com
A15: skillshare | B15: https://www.skillshare.com/en/profile/Seo-TheSpeedTrain/264027658 | C15: vital mobility | D15: auto login | E15: seo@thespeedtrain.com
A16: Start.me | B16: https://start.me/p/YQMjbq/start-page | C16: vital mobility | D16: auto login | E16: seo@thespeedtrain.com

Sheet Project Detail
B4: Project Details
B5: Brand Name | C5: Vital Mobility
B6: Domain Name | C6: https://vitalmobility.ca/
B7: Location | C7: 3 locations
B8: Description of Brand | C8: Canada’s Leading Medical Equipment Supplier & Rental Company
B9: Working Hours | C9: Mon-Fri 9am-5pm | Sat 10am-2pm | Sun Closed
B10: Instagram | C10: https://www.instagram.com/vitalmobilityhome/
B11: Linkedin | C11: https://www.linkedin.com/company/vital-mobility-home-healthcare/
B12: Facebook | C12: https://www.facebook.com/VitalMobility/
B13: Phone No. | C13: 905-532-9494
B14: Target Location | C14: Canada with £ locations
B15: Business Email (for business Listing and Directory) | C15: info@vitalmobility.ca
B16: Off-Page Details
B17: Email | C17: seo@thespeedtrain.com
B18: Password(Gmail) | C18: pooyaseo@thespeedtrain
B19: Username | C19: Vital Mobility

Sheet Report Summary
B4: White Hat SEO Work as per Google Panda and Penguin Algorithm
B6: Website:https://www.vitalmobility.ca/
B8: Sr.No | C8: Task | D8: Status
B9: 1 | C9: Keywords Ranking | D9: Done
B10: 2 | C10: Profile Creation | D10: Live
B11: 3 | C11: Social Bookmarking | D11: Live
B12: 4 | C12: Image Sharing | D12: Live
B13: 5 | C13: Web 2.0 Submission | D13: Live
B14: 6 | C14: Web 2.0 Blog Promotion | D14: Live
B15: 7 | C15: Blog Social Bookmarking | D15: Live
B16: 8 | C16: Local Citation submissions | D16: Live
B17: 9 | C17: Classified Submission | D17: Live
B18: 10 | C18: SEO+SMO Conjugation | D18: Live
B19: 11 | C19: Quora | D19: Live
B20: 12 | C20: Article submission | D20: Live
... B25: 17 | C25: Infographic Promotion | D25: Live

Sheet URL Mapping
B3: Keywords
B4: Website: https://www.vitalmobility.ca/
B5: Sr.No | C5: Keywords | D5: Landing Page
B6: 1
B7: 2
B8: 3
B9: 4
B10: 5
B11: 6
B12: 7
B13: 8
B14: 9
B15: 10
B16: 11
B17: 12
... B35: 30

Sheet Keywords Ranking
B3: Keywords Ranking
B4: Website: https://www.vitalmobility.ca/
B5: Sr.No | C5: Keywords | D5: Landing Page | I5: 45247 | J5: 45237 | K5: Initial Ranking Nov 1 2023
B6: 1 | I6: 13 | J6: 13 | K6: 12
B7: 2 | I7: N/A | J7: 64 | K7: N/A
B8: 3 | I8: 87 | J8: 86 | K8: 80
B9: 4 | I9: 61 | J9: 59 | K9: 77
B10: 5 | I10: 70 | J10: 70 | K10: 74
B11: 6 | I11: 74 | J11: 138 | K11: N/A
B12: 7 | I12: 17 | J12: 17 | K12: 13
B13: 8 | I13: 18 | J13: 17 | K13: 14
B14: 9 | I14: 32 | J14: 23 | K14: N/A
B15: 10 | I15: 12 | J15: 11 | K15: 45
B16: 11 | I16: 25 | J16: 23 | K16: 28
B17: 12 | I17: 41 | J17: 56 | K17: 56
B18: 13 | I18: 64 | J18: 76 | K18: 72
B19: 14 | I19: 47 | J19: 45 | K19: 57
B20: 15 | I20: N/A | J20: N/A | K20: N/A
B21: 16 | I21: 63 | J21: 66 | K21: 75
B22: 17 | I22: N/A | J22: N/A | K22: N/A
B23: 18 | I23: N/A | J23: N/A | K23: N/A
B24: 19 | I24: N/A | J24: N/A | K24: N/A
B25: 20 | I25: 94 | J25: 92 | K25: 92
B26: 21 | I26: N/A | J26: N/A | K26: N/A
B27: 22 | I27: N/A | J27: N/A | K27: N/A
B28: 23 | I28: 44 | J28: 47 | K28: 65
B29: 24 | I29: 54 | J29: 60 | K29: 57
B30: 25 | I30: 66 | J30: 60 | K30: N/A
B31: 26 | I31: 68 | J31: 70 | K31: 81
B32: 27 | I32: 96 | J32: N/A | K32: N/A
B33: 28 | I33: N/A | J33: N/A | K33: N/A
B34: 29 | I34: N/A | J34: N/A | K34: N/A
B35: 30 | I35: N/A | J35: N/A | K35: N/A

Sheet All Backlinks
G1: Backlinks with issue | H1: Issue | I1: From The section
A2: Social Bookmarking
A3: https://www.scoop.it/topic/vital-mobility-by-seo-thespeedtrain-com-10 | B3: seo@thespeedtrain.com | C3: pooyaseo@thespeedtrain | D3: Vital Mobility | E3: Live
A4: https://medium.com/@vitalmobility | B4: seo@thespeedtrain.com | C4: pooyaseo@thespeedtrain | D4: Vital Mobility | E4: Live
A5: https://folkd.com/profile/vitalmobality | B5: seo@thespeedtrain.com | C5: pooyaseo@thespeedtrain | D5: Vital Mobility | E5: Live
A6: https://wakelet.com/@vitalmobility | B6: seo@thespeedtrain.com | C6: pooyaseo@thespeedtrain | D6: Vital Mobility | E6: Live
A7: https://www.tumblr.com/hospitalbedsvit/722098665182887936/medical-equipment-supplier-rental-store-in?source=share | B7: seo@thespeedtrain.com | C7: pooyaseo@thespeedtrain | D7: Vital Mobility | E7: Live | F7: vpn
A8: https://www.evernote.com/shard/s630/sh/23790f0b-3d29-ddf4-bda0-a69312c445f7/C8umoHaRePm7hU1bINXkE6j8_O7E5YXsiMsr4CFihGWmTjU_dpgpKWobqQ | B8: seo@thespeedtrain.com | C8: pooyaseo@thespeedtrain | D8: Vital Mobility | E8: Live
A9: https://padlet.com/vitalmobility/my-fearless-padlet-ufq3jpn1hzcivktg | B9: seo@thespeedtrain.com | C9: pooyaseo@thespeedtrain | D9: Vital Mobility | E9: Live
A10: https://miro.com/miroverse/vital-mobility-medical-equipment-toronto/ | B10: seo@thespeedtrain.com | C10: pooyaseo@thespeedtrain | D10: Vital Mobility | E10: Live
A11: https://flipboard.com/@vitalmobility?from=share&utm_source=flipboard&utm_medium=curator_share | B11: seo@thespeedtrain.com | C11: pooyaseo@thespeedtrain | D11: Vital Mobility | E11: Live
A12: https://anotepad.com/note/read/8w6yjw8f | B12: seo@thespeedtrain.com | C12: pooyaseo@thespeedtrain | D12: Vital Mobility | E12: Live
A13: https://www.pearltrees.com/vitalmoility | B13: seo@thespeedtrain.com | C13: pooyaseo@thespeedtrain | D13: Vital Mobility | E13: Live
A14: https://rentry.co/zduen3ha | B14: seo@thespeedtrain.com | C14: RZ8tWGKh | D14: Vital Mobility | E14: Live
A15: https://www.zupyak.com/profile | B15: seo@thespeedtrain.com | C15: pooyaseo@thespeedtrain | D15: Vital Mobility | E15: Live
A16: Clssified Adds
A17: https://www.classifiedads.com/health_wellness/881c73gcp3dbx | B17: seo@thespeedtrain.com | C17: pooyaseo@thespeedtrain | D17: Vital Mobility | E17: Live
A19: Article Submission | C19: pooyaseo@thespeedtrain | D19: Vital Mobility | E19: Live
A20: https://diigo.com/0v2dxc | B20: seo@thespeedtrain.com | C20: pooyaseo@thespeedtrain | D20: Vital Mobility | E20: Live
A21: https://vitalmobality.livejournal.com/750.html | B21: seo@thespeedtrain.com | C21: k$br5Zs89E@wRg- | D21: Vital Mobility | E21: Live
A22: https://medium.com/@seo_66432/the-ultimate-guide-to-cold-therapy-machine-rentals-0d5d86c7cae3 | B22: seo@thespeedtrain.com | C22: pooyaseo@thespeedtrain | D22: Vital Mobility | E22: Live
A23: https://click4r.com/posts/u/6122497/Author-Vital | B23: seo@thespeedtrain.com | C23: pooyaseo@thespeedtrain | D23: Vital Mobility | E23: Live
A24: Article Promotion
A25: https://linktr.ee/vitalmobility | B25: seo@thespeedtrain.com | C25: pooyaseo@thespeedtrain | D25: Vital Mobility | E25: Live
A26: https://start.me/w/RQe99m | B26: seo@thespeedtrain.com | C26: pooyaseo@thespeedtrain | D26: Vital Mobility | E26: Live
A27: https://wibki.com/vitalmobality?tab=SeoTheSpeedTrain# | B27: seo@thespeedtrain.com | C27: pooyaseo@thespeedtrain | D27: Vital Mobility | E27: Live
A28: https://www.instapaper.com/read/1653922788 | B28: seo@thespeedtrain.com | C28: pooyaseo@thespeedtrain | D28: Vital Mobility | E28: Live
A29: https://raindrop.io/vitalmobality/vital-41343443 | B29: seo@thespeedtrain.com | C29: pooyaseo@thespeedtrain | D29: Vital Mobility | E29: Live
A30: https://contentle.com/vitalmobality/items | B30: seo@thespeedtrain.com | C30: pooyaseo@thespeedtrain | D30: Vital Mobility | E30: Live
A31: https://list.ly/list/9U6Y-vital-mobility-medical-equipment-toronto-medical-supply-toronto-wheelchair-rental?make_list_mode=true | B31: seo@thespeedtrain.com | C31: pooyaseo@thespeedtrain | D31: Vital Mobility | E31: Live
A32: https://www.symbaloo.com/shared/AAAABV8hRZUAA41_0gNuLQ== | B32: seo@thespeedtrain.com | C32: pooyaseo@thespeedtrain | D32: Vital Mobility | E32: Live
A33: https://papaly.com/vitalmobility/akgjq/httpswww-vitalmobility-ca | B33: seo@thespeedtrain.com | C33: pooyaseo@thespeedtrain | D33: Vital Mobility | E33: Live
A34: https://Link.Gallery/vitalmobility | B34: seo@thespeedtrain.com | C34: pooyaseo@thespeedtrain | D34: Vital Mobility | E34: Live
A35: https://atavi.com/share/whbgbnz1l9wfx | B35: seo@thespeedtrain.com | C35: pooyaseo@thespeedtrain | D35: Vital Mobility | E35: Live
A36: https://www.exchangle.com/vitalmobility | B36: seo@thespeedtrain.com | C36: pooyaseo@thespeedtrain | D36: Vital Mobility | E36: Live
... A39: https://heylink.me/seo424 | B39: seo@thespeedtrain.com | C39: pooyaseo@thespeedtrain | D39: Vital Mobility | E39: Live
A40: Press Release submission
A41: https://pressnews.biz/@vitalmobality/vital-mobility-medical-equipment-toronto-medical-supply-toronto-wheelchair-rental-afhn4ahstxbt | B41: seo@thespeedtrain.com | C41: vital123 | D41: Vital Mobility | E41: Live
A42: Local Ciatation
A43: https://www.provenexpert.com/vital-mobility/?_gl=1*14rhb1t*_ga*NDYxMTA4OTA4LjE3MDM1MDU5NTc.*_ga_9JZ6KME51R*MTcwMzUwNTk1Ni4xLjEuMTcwMzUwNzQwNC42LjAuMA.. | B43: seo@thespeedtrain.com | C43: pooyaseo@thespeedtrain | D43: Vital Mobility | E43: Live
...

Sheet Social Bookmarking
B2: Social Bookmarking
B3: https://www.vitalmobility.ca/
B6: Sr.No | C6: Website | D6: Gmail | E6: Password | F6: Target Keyword | G6: Target URL | H6: Live URL | I6: Status
B7: 1 | C7: https://www.scoop.it/ | D7: seo@thespeedtrain.com | E7: pooyaseo@thespeedtrain | F7: Vital mobility | G7: https://www.vitalmobility.ca/ | H7: https://sco.lt/6r0DD6 | I7: Live
B8: 2 | C8: https://medium.com/ | D8: seo@thespeedtrain.com | E8: pooyaseo@thespeedtrain | F8: Vital mobility | G8: https://www.vitalmobility.ca/ | H8: https://medium.com/@seo_66432 | I8: Live
B9: 3 | C9: http://www.folkd.com/ | D9: seo@thespeedtrain.com | E9: pooyaseo@thespeedtrain | F9: Vital mobility | G9: https://www.vitalmobility.ca/ | H9: https://folkd.com/profile/vitalmobality | I9: Live
B10: 4 | C10: https://wakelet.com/ | D10: seo@thespeedtrain.com | E10: pooyaseo@thespeedtrain | F10: Vital mobility | G10: https://www.vitalmobility.ca/ | H10: https://wakelet.com/@vitalmobility | I10: Live
B11: 5 | C11: https://www.tumblr.com/ | D11: seo@thespeedtrain.com | E11: pooyaseo@thespeedtrain | F11: Vital mobility | G11: https://www.vitalmobility.ca/ | H11: https://www.tumblr.com/hospitalbedsvit/722098665182887936/medical-equipment-supplier-rental-store-in?source=share | I11: Live
B13: Sr.No | C13: Website | D13: Gmail | E13: Password | F13: Target Keyword | G13: Target URL | H13: Live URL | I13: Status
B14: 1 | C14: https://evernote.com/ | D14: seo@thespeedtrain.com | E14: pooyaseo@thespeedtrain | F14: Vital mobility | G14: https://www.vitalmobility.ca/ | H14: https://www.evernote.com/client/web#/note/a170bb53-aeef-72c2-8990-a734d4b58339 | I14: Live
B15: 2 | C15: https://padlet.com/ | D15: seo@thespeedtrain.com | E15: pooyaseo@thespeedtrain | F15: Vital mobility | G15: https://www.vitalmobility.ca/ | H15: https://padlet.com/vitalmobility/my-fearless-padlet-ufq3jpn1hzcivktg | I15: Live
B16: 3 | C16: https://miro.com/ | D16: seo@thespeedtrain.com | E16: pooyaseo@thespeedtrain | F16: Vital mobility | G16: https://www.vitalmobility.ca/ | H16: https://miro.com/miroverse/submission/preview/3cRpX1VZc9uFoIVXQM7rXt/?backToUrl=%2Fconnected-health-kit-template%2F&id=3cRpX1VZc9uFoIVXQM7rXt | I16: Live
B17: 4 | C17: https://flipboard.com/ | D17: seo@thespeedtrain.com | E17: pooyaseo@thespeedtrain | F17: Vital mobility | G17: https://www.vitalmobility.ca/ | H17: https://flipboard.com/@vitalmobility?from=share&utm_source=flipboard&utm_medium=curator_share | I17: Live
B19: Sr.No | C19: Website | D19: Gmail | E19: Password | F19: Target Keyword | G19: Target URL | H19: Live URL | I19: Status
B20: 1 | C20: https://www.pinterest.com | D20: seo@thespeedtrain.com | E20: pooyaseo@thespeedtrain | F20: Vital mobility | G20: https://www.vitalmobility.ca/ | H20: https://www.pinterest.ca/pin/970807263411221643/ | I20: Live
B21: 2 | C21: https://www.instapaper.com/ | D21: seo@thespeedtrain.com | E21: pooyaseo@thespeedtrain | F21: Vital mobility | G21: https://www.vitalmobility.ca/ | H21: https://www.instapaper.com/u | I21: Live
B23: Sr.No | C23: Website | D23: Gmail | E23: Password | F23: Target Keyword | G23: Target URL | H23: Live URL | I23: Status
B24: 1 | C24: https://anotepad.com/ | D24: seo@thespeedtrain.com | E24: pooyaseo@thespeedtrain | F24: Vital mobility | G24: https://www.vitalmobility.ca/ | H24: https://anotepad.com/note/read/8w6yjw8f | I24: Live
B25: 2 | C25: https://www.pearltrees.com | D25: seo@thespeedtrain.com | E25: pooyaseo@thespeedtrain | F25: Vital mobility | G25: https://www.vitalmobility.ca/ | H25: https://www.pearltrees.com/vitalmoility | I25: Live
B26: 3 | C26: https://rentry.co/ | D26: seo@thespeedtrain.com | E26: pooyaseo@thespeedtrain | F26: Vital mobility | G26: https://www.vitalmobility.ca/ | H26: https://rentry.co/wa785 | I26: Live
B27: 4 | C27: https://www.zupyak.com/ | D27: seo@thespeedtrain.com | E27: pooyaseo@thespeedtrain | F27: Vital mobility | G27: https://www.vitalmobility.ca/ | H27: https://www.zupyak.com/profile | I27: Live
B29: Sr.No | C29: Website | D29: Gmail | E29: Password | F29: Target Keyword | G29: Target URL | H29: Live URL | I29: Status
B30: 1 | I30: Live
B31: 2 | I31: Live
B32: 3 | I32: Live
B33: 4 | I33: Live
B34: 5 | I34: Live
B36: Sr.No | C36: Website | D36: Gmail | E36: Password | F36: Target Keyword | G36: Target URL | H36: Live URL | I36: Status
B37: 1 | I37: Live
B38: 2 | I38: Live
B39: 3 | I39: Live
B40: 4 | I40: Live
B41: 5 | I41: Live
B42: 6 | I42: Live

Sheet Classified Ads
B2: Classified Submission
B3: Website - https://www.vitalmobility.ca/
B6: Sr.No | C6: Website | D6: Gmail | E6: Password | F6: Target Keyword | G6: Target URL | H6: Live URL | I6: Status
B7: 1 | C7: https://www.classifiedads.com | D7: seo@thespeedtrain.com | E7: pooyaseo@thespeedtrain | F7: Vital mobility | G7: https://www.vitalmobility.ca/ | H7: https://www.classifiedads.com/health_wellness/c8zb7y9km3dwd | I7: Live
B8: 2 | C8: https://www.muamat.com/ | I8: Live
B9: 3 | C9: www.adsthumb.com | I9: Live
B10: 4 | C10: https://freead1.net/ | I10: Live
B11: 5 | C11: https://www.adlandpro.com | I11: Live
B13: Sr.No | C13: Website | D13: Gmail | E13: Password | F13: Target Keyword | G13: Target URL | H13: Live URL | I13: Status
B14: 1 | C14: https://qwikad.com/ | I14: Live
B15: 2 | C15: https://www.expatriates.com/ | I15: Live
B16: 3 | C16: https://www.topclassifieds.com/ | I16: Live
B17: 4 | C17: https://www.adproceed.com/ | I17: Live
B18: 5 | C18: http://www.locanto.com/ | I18: Live
B20: Sr.No | C20: Website | D20: Gmail | E20: Password | F20: Target Keyword | G20: Target URL | H20: Live URL | I20: Status
B21: 1 | C21: https://classified4u.biz/ | I21: Live
B22: 2 | C22: https://www.classifiedads.com | I22: Live
B23: 3 | C23: https://classifieds4free.biz/ | I23: Live
B25: Sr.No | C25: Website | D25: Gmail | E25: Password | F25: Target Keyword | G25: Target URL | H25: Live URL | I25: Status
B26: 1 | C26: https://www.classifiedads.com | I26: Live
B27: 2 | C27: https://www.muamat.com/ | I27: Live
B28: 3 | C28: www.adsthumb.com | I28: Live
B29: 4 | C29: https://freead1.net/ | I29: Live
B30: 5 | C30: https://www.adlandpro.com | I30: Live
B32: Sr.No | C32: Website | D32: Gmail | E32: Password | F32: Target Keyword | G32: Target URL | H32: Live URL | I32: Status
B33: 1 | C33: https://www.expatriates.com/ | I33: Live
B34: 2 | C34: https://classified4u.biz/ | I34: Live
B35: 3 | C35: https://www.adproceed.com/ | I35: Live
B36: 4 | C36: https://www.adpost4u.com | I36: Live
B37: 5 | C37: http://www.usnetads.com/ | I37: Live
B38: 6 | C38: https://MyPetAds.com/ | I38: Live
B40: Sr.No | C40: Website | D40: Gmail | E40: Password | F40: Target Keyword | G40: Target URL | H40: Live URL | I40: Status
B41: 1 | C41: https://nextfreeads.com/ | I41: Live
B42: 2 | C42: https://us.classi4u.com/ | I42: Live
B43: 3 | C43: https://GlobalClassified.net/ | I43: Live
B44: 4 | C44: https://letspostfree.com/ | I44: Live
B45: 5 | C45: https://classifieds4free.biz/ | I45: Live

Sheet Article Submission
B2: Article submission
B3: Website - https://www.vitalmobility.ca/
B6: Sr.No | C6: Website | D6: Gmail | E6: Password | F6: Target URL | G6: Live URL | H6: Status
B7: 1 | C7: https://www.diigo.com/ | D7: seo@thespeedtrain.com | E7: pooyaseo@thespeedtrain | F7: https://www.vitalmobility.ca/ | G7: https://diigo.com/0v2dxc | H7: Live
B9: Sr.No | C9: Website | D9: Gmail | E9: Password | F9: Target URL | G9: Live URL | H9: Status
B10: 1 | C10: https://www.livejournal.com/ | D10: seo@thespeedtrain.com | E10: k$br5Zs89E@wRg- | F10: https://www.vitalmobility.ca/ | G10: https://vitalmobality.livejournal.com/750.html | H10: Live
B13: Sr.No | C13: Website | D13: Gmail | E13: Password | F13: Target URL | G13: Live URL | H13: Status
B14: 1 | C14: https://medium.com/ | D14: seo@thespeedtrain.com | E14: pooyaseo@thespeedtrain | F14: https://www.vitalmobility.ca/ | G14: https://medium.com/@seo_66432/the-ultimate-guide-to-cold-therapy-machine-rentals-0d5d86c7cae3 | H14: Live
B17: Sr.No | C17: Website | D17: Gmail | E17: Password | F17: Target URL | G17: Live URL | H17: Status
B18: 1 | C18: https://click4r.com/ | D18: seo@thespeedtrain.com | E18: pooyaseo@thespeedtrain | F18: https://www.vitalmobility.ca/ | G18: https://click4r.com/posts/u/6122497/Author-Vital | H18: Live

Sheet Article Promotion
B2: Article Promotion Promotion
B3: Website - https://www.vitalmobility.ca/
B6: Sr.No | C6: Website | D6: Gmail | E6: Password | F6: Target URL | G6: Live URL | H6: Status
B7: 1 | C7: https://linktr.ee/ | D7: seo@thespeedtrain.com | E7: pooyaseo@thespeedtrain | F7: https://www.vitalmobility.ca/ | G7: https://linktr.ee/vitalmobility | H7: Live
B8: 2 | C8: https://start.me/ | D8: seo@thespeedtrain.com | E8: pooyaseo@thespeedtrain | F8: https://www.vitalmobility.ca/ | G8: https://start.me/w/RQe99m | H8: Live
B9: 3 | C9: https://www.wibki.com/ | D9: seo@thespeedtrain.com | E9: pooyaseo@thespeedtrain | F9: https://www.vitalmobility.ca/ | G9: https://wibki.com/vitalmobality?tab=SeoTheSpeedTrain# | H9: Live
B10: 4 | C10: https://www.instapaper.com/ | D10: seo@thespeedtrain.com | E10: pooyaseo@thespeedtrain | F10: https://www.vitalmobility.ca/ | G10: https://www.instapaper.com/read/1653922788 | H10: Live
B12: Sr.No | C12: Website | D12: Gmail | E12: Password | F12: Target URL | G12: Live URL | H12: Status
B13: 1 | C13: https://raindrop.io | D13: seo@thespeedtrain.com | E13: pooyaseo@thespeedtrain | F13: https://www.vitalmobility.ca/ | G13: https://raindrop.io/vitalmobality/vital-41343443 | H13: Live
B14: 2 | C14: https://contentle.com/ | D14: seo@thespeedtrain.com | E14: pooyaseo@thespeedtrain | F14: https://www.vitalmobility.ca/ | G14: https://contentle.com/vitalmobality/items | H14: Live
B15: 3 | C15: https://list.ly/ | D15: seo@thespeedtrain.com | E15: pooyaseo@thespeedtrain | F15: https://www.vitalmobility.ca/ | G15: https://list.ly/list/9U6Y-vital-mobility-medical-equipment-toronto-medical-supply-toronto-wheelchair-rental?make_list_mode=true | H15: Live
B16: 4 | C16: https://www.symbaloo.com/ | D16: seo@thespeedtrain.com | E16: pooyaseo@thespeedtrain | F16: https://www.vitalmobility.ca/ | G16: https://www.symbaloo.com/shared/AAAABV8hRZUAA41_0gNuLQ== | H16: Live
B18: Sr.No | C18: Website | D18: Gmail | E18: Password | F18: Target URL | G18: Live URL | H18: Status
B19: 1 | C19: https://papaly.com | D19: seo@thespeedtrain.com | E19: pooyaseo@thespeedtrain | F19: https://www.vitalmobility.ca/ | G19: https://papaly.com/vitalmobility/akgjq/httpswww-vitalmobility-ca | H19: Live
B20: 2 | C20: https://www.rebrandly.com/ | D20: seo@thespeedtrain.com | E20: pooyaseo@thespeedtrain | F20: https://www.vitalmobility.ca/ | G20: https://Link.Gallery/vitalmobility | H20: Live
B21: 3 | C21: https://atavi.com/ | D21: seo@thespeedtrain.com | E21: pooyaseo@thespeedtrain | F21: https://www.vitalmobility.ca/ | G21: https://atavi.com/share/whbgbnz1l9wfx | H21: Live
B22: 4 | C22: https://www.exchangle.com/ | D22: seo@thespeedtrain.com | E22: pooyaseo@thespeedtrain | F22: https://www.vitalmobility.ca/ | G22: https://www.exchangle.com/vitalmobility | H22: Live
B24: Sr.No | C24: Website | D24: Gmail | E24: Password | F24: Target URL | G24: Live URL | H24: Status
B25: 1 | C25: https://allmylinks.com/ | D25: seo@thespeedtrain.com | E25: pooyaseo@thespeedtrain | F25: https://www.vitalmobility.ca/ | G25: https://allmylinks.com/vitalmobility | H25: Live
B26: 2 | C26: https://socialrus.com/ | D26: seo@thespeedtrain.com | E26: pooyaseo@thespeedtrain | F26: https://www.vitalmobility.ca/ | G26: https://socialrus.com/story16086945/vital-mobility-medical-equipment-toronto-medical-supply-toronto-wheelchair-rental#discuss | H26: Live
B28: Sr.No | C28: Website | D28: Gmail | E28: Password | F28: Target URL | G28: Live URL | H28: Status
B29: 1 | C29: https://app.heylink.me/ | D29: seo@thespeedtrain.com | E29: pooyaseo@thespeedtrain | F29: https://www.vitalmobility.ca/ | G29: https://heylink.me/seo424 | H29: Live

Sheet Guest Post Submission
B2: Guest Post Submission
B5: Website: https://houseremovalistsmelbourne.net.au/
B9: Sr.No | C9: Submission Site | D9: Gmail Id | E9: Password | F9: Post URL | G9: Keyword | H9: Target URL | I9: Status
B10: 1 | C10: https://beforeitsnews.com/ | I10: Live

Sheet Press Release Submission
B2: Press Release Submission
B3: Website - https://www.vitalmobility.ca/
B6: Sr.No | C6: Website | D6: Gmail | E6: Password | F6: Target URL | G6: Live URL | H6: Status
B7: 1 | C7: https://www.issuewire.com/ | G7: Paid
B8: 45244
B9: Sr.No | C9: Website | D9: Gmail | E9: Password | F9: Target URL | G9: Live URL | H9: Status
B10: 1 | C10: https://www.pressnews.biz/ | D10: seo@thespeedtrain.com | E10: vital123 | F10: https://www.vitalmobility.ca/ | G10: https://pressnews.biz/@vitalmobality/vital-mobility-medical-equipment-toronto-medical-supply-toronto-wheelchair-rental-afhn4ahstxbt | H10: Live
B11: 45253
B12: Sr.No | C12: Website | D12: Gmail | E12: Password | F12: Target URL | G12: Live URL | H12: Status
B13: 1 | C13: https://express-press-release.net/ | D13: seo@thespeedtrain.com | F13: https://www.vitalmobility.ca/ | G13: In Draft | H13: Live

Sheet Web 2.0 Blog Submission
B2: Web 2.0 Submission
B3: Website - https://www.vitalmobility.ca/
B6: Sr.No | C6: Website | D6: Gmail | E6: Password | F6: Target URL | G6: Live URL | H6: Status
B7: 1 | C7: https://www.blogger.com/ | H7: Live
B9: Sr.No | C9: Website | D9: Gmail | E9: Password | F9: Target URL | G9: Live URL | H9: Status
B10: 1 | C10: https://techplanet.today/ | H10: Live
B12: Sr.No | C12: Website | D12: Gmail | E12: Password | F12: Target URL | G12: Live URL | H12: Status
B13: 1 | C13: https://www.notion.so/ | H13: Live
B15: Sr.No | C15: Website | D15: Gmail | E15: Password | F15: Target URL | G15: Live URL | H15: Status
B16: 1 | C16: https://www.reddit.com/ | H16: Live

Sheet Local Citation
B2: Local Citation submissions
B3: Website - https://www.vitalmobility.ca/
B6: Sr.No | C6: Website | D6: Gmail | E6: Password | F6: Live URL | G6: Status
B7: 1 | C7: https://www.provenexpert.com/ | D7: seo@thespeedtrain.com | E7: pooyaseo@thespeedtrain | F7: https://www.provenexpert.com/vital-mobility/?_gl=1*14rhb1t*_ga*NDYxMTA4OTA4LjE3MDM1MDU5NTc.*_ga_9JZ6KME51R*MTcwMzUwNTk1Ni4xLjEuMTcwMzUwNzQwNC42LjAuMA.. | G7: Live
B8: 2 | C8: https://www.brownbook.net/ | D8: seo@thespeedtrain.com | E8: pooyaseo@thespeedtrain | F8: https://www.brownbook.net/business/52338609/vital-mobility/ | G8: Live
B11: Sr.No | C11: Website | D11: Gmail | E11: Password | F11: Live URL | G11: Status
B12: 1 | C12: https://www.techdirectory.io | D12: seo@thespeedtrain.com | E12: pooyaseo@thespeedtrain | F12: https://www.techdirectory.io/canada/health-technology/vital-mobility | G12: Live
B13: 2 | C13: https://au.enrollbusiness.com/ | D13: seo@thespeedtrain.com | E13: pooyaseo@thespeedtrain | F13: https://au.enrollbusiness.com/BusinessProfile/6506847/Vital%20Mobility | G13: Live
B15: Sr.No | C15: Website | D15: Gmail | E15: Password | F15: Live URL | G15: Status
B16: 1 | C16: https://www.localbusinesslisting.org/ | D16: seo@thespeedtrain.com | E16: pooyaseo@thespeedtrain | F16: https://www.localbusinesslisting.org/vital-mobility | G16: Live
B17: 2 | C17: http://www.golocalezservices.com/ | D17: seo@thespeedtrain.com | E17: pooyaseo@thespeedtrain | F17: http://www.golocalezservices.com/canada/health-fitness/vital-mobility | G17: Live
B19: Sr.No | C19: Website | D19: Gmail | E19: Password | F19: Live URL | G19: Status
B20: 1 | C20: https://foursquare.com/ | D20: seo@thespeedtrain.com | E20: pooyaseo@thespeedtrain | F20: https://foursquare.com/vitalm7735738/list/vital-mobility-home-health-care-equipment-supplier | G20: Live
B23: Sr.No | C23: Website | D23: Gmail | E23: Password | F23: Live URL | G23: Status
B24: 1 | C24: https://www.cargodirectory.co/ | D24: seo@thespeedtrain.com | E24: pooyaseo@thespeedtrain | F24: https://www.cargodirectory.co/canada/health-care-services/vital-mobility | G24: Live
B25: 2 | C25: https://www.successcenter.com/ | D25: seo@thespeedtrain.com | E25: pooyaseo@thespeedtrain | F25: https://www.successcenter.com/ontario/concord/services/vital-mobility | G25: Live
B26: 3 | C26: https://www.localhomeservicepros.com | D26: seo@thespeedtrain.com | E26: pooyaseo@thespeedtrain | F26: https://www.localhomeservicepros.com/canada/health-care/vital-mobility | G26: Live
B27: 4 | C27: https://www.bestincom.com/ | D27: seo@thespeedtrain.com | E27: pooyaseo@thespeedtrain | F27: https://www.bestincom.com/canada/health-care/vital-mobility | G27: Live

Sheet Press Release Promotion
B2: Press Release Promotion
B3: Website - https://www.vitalmobility.ca/
B6: Sr.No | C6: Website | D6: Gmail | E6: Password | F6: Target URL | G6: Live URL | H6: Status
B7: 1 | C7: https://papaly.com | H7: Live
B8: 2 | C8: https://www.rebrandly.com/ | H8: Live
B9: 3 | C9: https://atavi.com/ | H9: Live
B10: 4 | C10: https://www.symbaloo.com/ | H10: Live
B12: Sr.No | C12: Website | D12: Gmail | E12: Password | F12: Target URL | G12: Live URL | H12: Status
B13: 1 | C13: https://www.exchangle.com/ | H13: Live
B14: 2 | C14: https://raindrop.io | H14: Live
B15: 3 | C15: https://www.scoop.it | H15: Live
B17: Sr.No | C17: Website | D17: Gmail | E17: Password | F17: Target URL | G17: Live URL | H17: Status
B18: 1 | C18: https://linktr.ee/ | H18: Live
B19: 2 | C19: https://start.me/ | H19: Live
B20: 3 | C20: https://www.wibki.com/ | H20: Live
B21: 4 | C21: https://allmylinks.com/ | H21: Live

Sheet Web 2.0 Blog Promotion
B2: Web 2.0 Blog Promotion
B3: Website - https://www.vitalmobility.ca/
B6: Sr.No | C6: Website | D6: Gmail | E6: Password | F6: Target URL | G6: Live URL | H6: Status
B7: 1 | C7: https://papaly.com | H7: Live
B8: 2 | C8: https://www.rebrandly.com/ | H8: Live
B9: 3 | C9: https://www.symbaloo.com/ | H9: Live
B10: 4 | C10: https://www.exchangle.com/ | H10: Live
B11: 5 | C11: https://raindrop.io | H11: Live
B13: Sr.No | C13: Website | D13: Gmail | E13: Password | F13: Target URL | G13: Live URL | H13: Status
B14: 1 | C14: https://linktr.ee/ | H14: Live
B15: 2 | C15: https://www.scoop.it/ | H15: Live
B16: 3 | C16: https://atavi.com/ | H16: Live
B17: 4 | C17: https://allmylinks.com/ | H17: Live
B19: Sr.No | C19: Website | D19: Gmail | E19: Password | F19: Target URL | G19: Live URL | H19: Status
B20: 1 | C20: https://www.instapaper.com/ | H20: Live
B21: 2 | C21: https://start.me/ | H21: Live
B22: 3 | C22: https://www.wibki.com/ | H22: Live
B23: 4 | C23: https://www.pearltrees.com/ | H23: Live
B25: Sr.No | C25: Website | D25: Gmail | E25: Password | F25: Target URL | G25: Live URL | H25: Status
B26: 1 | C26: https://papaly.com | H26: Live
B27: 2 | C27: https://www.rebrandly.com/ | H27: Live
B28: 3 | C28: https://www.symbaloo.com/ | H28: Live
B29: 4 | C29: https://www.exchangle.com/ | H29: Live
B30: 4 | C30: https://raindrop.io | H30: Live

Sheet Image Submission
B3: Image Sharing
B4: Website - https://www.vitalmobility.ca
B7: Sr.No | C7: Website | D7: Gmail | E7: Password | F7: Target Keyword | G7: Target URL | H7: Live URL | I7: Status
B8: 1 | C8: https://www.pinterest.com/ | I8: Live
B9: 2 | C9: https://www.behance.net | I9: Live
B10: 3 | C10: https://justpaste.it/ | I10: Live
B11: 4 | C11: https://gab.com/ | I11: Live
B12: 5 | C12: http://www.mediafire.com/ | I12: Live
B14: Sr.No | C14: Website | D14: Gmail | E14: Password | F14: Target Keyword | G14: Target URL | H14: Live URL | I14: Status
B15: 1 | C15: https://imgur.com/ | I15: Live
B16: 2 | C16: https://wakelet.com/ | I16: Live
B17: 3 | C17: https://www.imagevenue.com/ | I17: Live
B18: 4 | C18: https://www.diigo.com/ | I18: Live
B19: 5 | C19: https://www.tumblr.com/ | I19: Live
B24: 3 | C24: https://www.4shared.com/ | I24: Live
B25: 4 | C25: https://imgbb.com/ | I25: Live
B26: 5 | C26: https://wakelet.com/ | I26: Live
B28: 45272
B29: Sr.No | C29: Website | D29: Gmail | E29: Password | F29: Target Keyword | G29: Target URL | H29: Live URL | I29: Status
B30: 1 | C30: https://500px.com/ | I30: Live
B33: 45273
B34: Sr.No | C34: Website | D34: Gmail | E34: Password | F34: Target Keyword | G34: Target URL | H34: Live URL | I34: Status
B35: 1 | C35: https://dribbble.com/ | I35: Live
B36: 2 | C36: https://www.scoop.it/ | I36: Live
B37: 2 | C37: https://justpaste.me/ | I37: Live

Sheet Profile Creation
B2: Profile Creation
B3: Website - https://www.vitalmobility.ca/
B6: Sr.No | C6: Website | D6: Gmail | E6: Password | F6: Target Url | G6: Profile Link | H6: Status
B7: 1 | C7: https://medium.com/ | D7: seo@thespeedtrain.com | E7: pooyaseo@thespeedtrain | F7: https://www.vitalmobility.ca/ | G7: https://medium.com/@seo_66432 | H7: Live
B8: 2 | C8: https://www.behance.net/ | D8: seo@thespeedtrain.com | E8: pooyaseo@thespeedtrain | F8: https://www.vitalmobility.ca/ | G8: https://www.behance.net/vitalmobility | H8: Live
B9: 3 | C9: https://justpaste.it/ | D9: seo@thespeedtrain.com | E9: pooyaseo@thespeedtrain | F9: https://www.vitalmobility.ca/ | G9: https://justpaste.it/u/Vital_Mobility | H9: Live
B11: Sr.No | C11: Website | D11: Gmail | E11: Password | F11: Target Url | G11: Profile Link | H11: Status
B12: 1 | C12: https://imgur.com/ | D12: seo@thespeedtrain.com | E12: pooyaseo@thespeedtrain | F12: https://www.vitalmobility.ca/ | G12: https://imgur.com/gallery/otT7uU8 | H12: Live
B13: 2 | C13: https://folkd.com/ | D13: seo@thespeedtrain.com | E13: pooyaseo@thespeedtrain | F13: https://www.vitalmobility.ca/ | G13: https://folkd.com/profile/vitalmobality | H13: Live
B14: 3 | C14: https://www.tumblr.com/ | D14: seo@thespeedtrain.com | E14: pooyaseo@thespeedtrain | F14: https://www.vitalmobility.ca/ | G14: https://www.tumblr.com/hospitalbedsvit/722098665182887936/medical-equipment-supplier-rental-store-in?source=share | H14: Live
B16: Sr.No | C16: Website | D16: Gmail | E16: Password | F16: Target Url | G16: Profile Link | H16: Status
B17: 1 | C17: https://www.provenexpert.com/ | D17: seo@thespeedtrain.com | E17: pooyaseo@thespeedtrain | F17: https://www.vitalmobility.ca/ | G17: https://www.provenexpert.com/vital-mobility/?_gl=1*14rhb1t*_ga*NDYxMTA4OTA4LjE3MDM1MDU5NTc.*_ga_9JZ6KME51R*MTcwMzUwNTk1Ni4xLjEuMTcwMzUwNzQwNC42LjAuMA.. | H17: Live
B18: 2 | C18: https://www.reddit.com/ | D18: seo@thespeedtrain.com | E18: pooyaseo@thespeedtrain | F18: https://www.vitalmobility.ca/ | G18: https://www.reddit.com/user/vitalmobality/ | H18: Live
B20: Sr.No | C20: Website | D20: Gmail | E20: Password | F20: Target Url | G20: Profile Link | H20: Status
B21: 1 | C21: https://imgur.com/ | D21: seo@thespeedtrain.com | E21: pooyaseo@thespeedtrain | F21: https://www.vitalmobility.ca/ | H21: Live
B22: 2 | C22: https://voiccing.com/ | H22: Live
B23: 3 | C23: https://about.me/ | H23: Live
B26: Sr.No | C26: Website | D26: Gmail | E26: Password | F26: Target Url | G26: Profile Link | H26: Status
B27: 1 | C27: https://gitea.blesmrt.net/ | D27: seo@thespeedtrain.com | E27: pooyaseo@thespeedtrain | F27: https://www.vitalmobility.ca/ | H27: Live
B28: 2 | C28: https://land-book.com/ | H28: Live
B29: 3 | C29: https://club.vexanium.com/ | H29: Live
B30: 4 | C30: https://community.theconstructor.org/ | H30: Live
B31: 5 | C31: https://packinsider.com/ | H31: Live
B32: 6 | C32: https://www.notebook.ai/ | H32: Live

Sheet Profile Link Updation
B2: Profile Link Updation
B3: Website - https://www.vitalmobility.ca/
B6: Sr.No | C6: Website | D6: Gmail | E6: Password | F6: Profile Link | G6: Status
B7: 1 | C7: https://medium.com/ | D7: seo@thespeedtrain.com | E7: pooyaseo@thespeedtrain | F7: https://medium.com/@seo_66432 | G7: Live
B8: 2 | C8: https://www.behance.net/ | D8: seo@thespeedtrain.com | E8: pooyaseo@thespeedtrain | F8: https://www.behance.net/vitalmobility | G8: Live
B9: 3 | C9: https://justpaste.it/ | D9: seo@thespeedtrain.com | E9: pooyaseo@thespeedtrain | F9: https://justpaste.it/u/Vital_Mobility | G9: Live
B10: 4 | C10: https://imgur.com/ | D10: seo@thespeedtrain.com | E10: pooyaseo@thespeedtrain | F10: https://imgur.com/gallery/otT7uU8 | G10: Live
B12: Sr.No | C12: Website | D12: Gmail | E12: Password | F12: Profile Link | G12: Live
B13: 1 | C13: https://folkd.com/ | D13: seo@thespeedtrain.com | E13: pooyaseo@thespeedtrain | F13: https://folkd.com/profile/vitalmobality | G13: Live
B14: 2 | C14: https://www.tumblr.com/ | D14: seo@thespeedtrain.com | E14: pooyaseo@thespeedtrain | F14: https://www.tumblr.com/hospitalbedsvit/722098665182887936/medical-equipment-supplier-rental-store-in?source=share | G14: Live
B15: 3 | C15: https://www.provenexpert.com/ | D15: seo@thespeedtrain.com | E15: pooyaseo@thespeedtrain | F15: https://www.provenexpert.com/vital-mobility/?_gl=1*14rhb1t*_ga*NDYxMTA4OTA4LjE3MDM1MDU5NTc.*_ga_9JZ6KME51R*MTcwMzUwNTk1Ni4xLjEuMTcwMzUwNzQwNC42LjAuMA.. | G15: Live
B16: 4 | C16: https://www.reddit.com/ | D16: seo@thespeedtrain.com | E16: pooyaseo@thespeedtrain | F16: https://www.reddit.com/user/vitalmobality | G16: Live

Sheet Forum Submission
B2: Forum Submission
B3: Website - https://www.vitalmobility.ca/
B6: Sr.No | C6: Website | D6: Gmail | E6: Password | F6: Target Url | G6: Profile Link | H6: Status
B7: 1 | C7: https://forums.beyondunreal.com/ | H7: Live
B8: 2 | C8: https://forum.promise.com/ | H8: Live
B9: 3 | C9: https://www.warriorforum.com/ | H9: Live

Sheet SEO+SMO Conjugation
B2: SEO+SMO Conjugation
B3: Website - https://www.vitalmobility.ca/
B6: Sr.No | C6: Website | D6: Gmail | E6: Password | F6: Target Keyword | G6: Target URL | H6: Live URL | I6: Status
B7: 1 | C7: https://www.reddit.com/ | D7: seo@thespeedtrain.com | E7: vital321 | F7: vital mobility | G7: https://www.vitalmobility.ca/electric-hospital-bed.php | H7: https://www.reddit.com/r/chemicalreactiongifs/comments/1ajggs0/vitalmobility/?utm_source=share&utm_medium=web2x&context=3 | I7: Live
B8: 2 | C8: https://www.livejournal.com/ | D8: seo@thespeedtrain.com | E8: vital321 | F8: vital mobility | G8: https://www.vitalmobility.ca/electric-hospital-bed.php | H8: https://vitalmobality.livejournal.com/943.html | I8: Live
B9: 3 | C9: https://evernote.com/ | D9: seo@thespeedtrain.com | E9: vital321 | F9: vital mobility | G9: https://www.vitalmobility.ca/electric-hospital-bed.php | H9: https://www.evernote.com/shard/s630/sh/23790f0b-3d29-ddf4-bda0-a69312c445f7/C8umoHaRePm7hU1bINXkE6j8_O7E5YXsiMsr4CFihGWmTjU_dpgpKWobqQ | I9: Live
B11: Sr.No | C11: Website | D11: Gmail | E11: Password | F11: Target Keyword | G11: Target URL | H11: Live URL | I11: Status
B12: 1 | I12: Live
B13: 2 | I13: Live
B14: 3 | I14: Live
B16: Sr.No | C16: Website | D16: Gmail | E16: Password | F16: Target Keyword | G16: Target URL | H16: Live URL | I16: Status
B17: 1 | C17: https://medium.com/ | D17: seo@thespeedtrain.com | E17: vital321 | F17: vital mobility | G17: https://www.vitalmobility.ca/electric-hospital-bed.php | H17: https://medium.com/@vitalmobility/vital-mobility-c175f9b5b142 | I17: Live
B18: 2 | C18: https://www.diigo.com/ | D18: seo@thespeedtrain.com | E18: vital321 | F18: vital mobility | G18: https://www.vitalmobility.ca/electric-hospital-bed.php | H18: https://diigo.com/0v9u2q | I18: Live

Sheet Quora
B2: Quora
B3: Website - https://www.vitalmobility.ca/
B6: Sr.No | C6: Website | D6: Live URL | E6: Status
B7: 1 | C7: https://www.quora.com/ | D7: https://qr.ae/pKd9yW | E7: Live
B8: 2 | C8: https://www.quora.com/ | D8: https://qr.ae/pKd9yc | E8: Live
B10: Sr.No | C10: Website | D10: Live URL | E10: Status
B11: 1 | C11: https://www.quora.com/ | D11: https://qr.ae/pKd9sc | E11: Live
B12: 2 | C12: https://www.quora.com/ | D12: https://qr.ae/pKd9YX | E12: Live
B14: Sr.No | C14: Website | D14: Live URL | E14: Status
B15: 1 | C15: https://www.quora.com/ | D15: https://qr.ae/pKd9YP | E15: Live
B16: 2 | C16: https://www.quora.com/ | D16: https://qr.ae/pKd9Fh | E16: Live
B18: Sr.No | C18: Website | D18: Live URL | E18: Status
B19: 1 | C19: https://www.quora.com/ | D19: https://qr.ae/pKd9oj | E19: Live
B20: 2 | C20: https://www.quora.com/ | D20: https://qr.ae/pKd9PK | E20: Live
B21: 3 | C21: https://www.quora.com/ | D21: https://qr.ae/pKd9oO | E21: Live

Sheet Blog Social Bookmarking
B2: Blog Social Bookmarking
B3: Website -https://www.vitalmobility.ca/
B6: Sr.No | C6: Website | D6: Gmail | E6: Password | F6: Target URL | G6: Live URL | H6: Status
B7: 1 | C7: https://papaly.com | H7: Live
B8: 2 | C8: https://www.rebrandly.com/ | H8: Live
B9: 3 | C9: https://atavi.com/ | H9: Live
B10: 4 | C10: https://www.symbaloo.com/ | H10: Live
B11: 5 | C11: https://www.instapaper.com/ | H11: Live
B13: Sr.No | C13: Website | D13: Gmail | E13: Password | F13: Target URL | G13: Live URL | H13: Status
B14: 1 | C14: https://linktr.ee/ | H14: Live
B15: 2 | C15: https://www.scoop.it/ | H15: Live
B16: 3 | C16: https://allmylinks.com/ | H16: Live
B17: 4 | C17: https://contentle.com/ | H17: Live
B18: 5 | C18: https://www.exchangle.com/ | H18: Live
B20: Sr.No | C20: Website | D20: Gmail | E20: Password | F20: Target URL | G20: Live URL | H20: Status
B21: 1 | C21: https://start.me/ | H21: Live
B22: 2 | C22: https://www.wibki.com/ | H22: Live
B23: 3 | C23: https://raindrop.io | H23: Live
B24: 4 | C24: https://homepage.ninja/ | H24: Live
B25: 5 | C25: https://app.rebrandly.com/ | H25: Live
B27: Sr.No | C27: Website | D27: Gmail | E27: Password | F27: Target URL | G27: Live URL | H27: Status
B28: 1 | C28: https://atavi.com/ | H28: Live
B29: 2 | C29: https://www.symbaloo.com/ | H29: Live
B30: 3 | C30: https://www.instapaper.com/ | H30: Live
B31: 4 | C31: https://papaly.com | H31: Live
B32: 5 | C32: https://www.rebrandly.com/ | H32: Live

Sheet Infographic Submission
B2: Infographic Submission
B3: Website - https://www.vitalmobility.ca/
B6: Sr.No | C6: Website | D6: Gmail | E6: Password | F6: Target URL | G6: Live URL | H6: Status
B7: 1 | C7: https://www.pinterest.com | D7: seo@thespeedtrain.com | E7: pooyaseo@thespeedtrain | F7: https://www.vitalmobility.ca/ | G7: https://pin.it/75p05GLXA | H7: Live
B8: 2 | C8: https://www.4shared.com/ | D8: seo@thespeedtrain.com | E8: pooyaseo@thespeedtrain | F8: https://www.vitalmobility.ca/ | G8: https://www.4shared.com/s/flMlRJo0Cfa | H8: Live
B9: 3 | C9: https://app.mediafire.com/ | D9: seo@thespeedtrain.com | E9: pooyaseo@thespeedtrain | F9: https://www.vitalmobility.ca/ | G9: https://www.mediafire.com/file/mx34z35w86rjtxo/Green_Modern_Medical_Service_Poster.pdf/file | H9: Live
B10: 4 | C10: https://www.dropbox.com/ | D10: seo@thespeedtrain.com | E10: pooyaseo@thespeedtrain | F10: https://www.vitalmobility.ca/ | G10: https://www.dropbox.com/scl/fi/bupldepe5h15dppl6osbm/Green-Modern-Medical-Service-Poster.pdf?rlkey=myjt958b8nr2i0la8k5jx5poy&dl=0 | H10: Live
B11: 5 | C11: https://postimg.cc/ | D11: seo@thespeedtrain.com | E11: sPpxxZwFQKVr | F11: https://www.vitalmobility.ca/ | G11: https://i.postimg.cc/44Qv6YmQ/Green-Modern-Medical-Service-Poster.png | H11: Live
B13: Sr.No | C13: Website | D13: Gmail | E13: Password | F13: Target URL | G13: Live URL | H13: Status
B14: 1 | C14: https://wakelet.com/ | D14: seo@thespeedtrain.com | E14: pooyaseo@thespeedtrain | F14: https://www.vitalmobility.ca/ | G14: https://wakelet.com/i/invite?code=3ruzahid | H14: Live
B15: 2 | C15: https://photos.google.com/ | D15: seo@thespeedtrain.com | E15: pooyaseo@thespeedtrain | F15: https://www.vitalmobility.ca/ | G15: https://photos.app.goo.gl/RTej94ZqSjCqJB4d7 | H15: Live
B16: 3 | C16: https://docs.zoho.com | D16: seo@thespeedtrain.com | E16: pooyaseo@thespeedtrain | F16: https://www.vitalmobility.ca/ | G16: https://workdrive.zoho.com/file/4594wf2e1a707178a4411966a01acc30e5c42 | H16: Live
B17: 4 | C17: https://www.edocr.com/ | D17: seo@thespeedtrain.com | E17: pooyaseo@thespeedtrain | F17: https://www.vitalmobility.ca/ | G17: https://www.edocr.com/v/9x7gmxb5/vitalmobility1/green-modern-medical-service-poster | H17: Live
B18: 5 | C18: https://www.diigo.com/ | D18: seo@thespeedtrain.com | E18: pooyaseo@thespeedtrain | F18: https://www.vitalmobility.ca/ | G18: https://diigo.com/0v7l0r | H18: Live
B20: Sr.No | C20: Website | D20: Gmail | E20: Password | F20: Target URL | G20: Live URL | H20: Status
B21: 1 | C21: https://www.tumblr.com/ | D21: seo@thespeedtrain.com | E21: pooyaseo@thespeedtrain | F21: https://www.vitalmobility.ca/ | G21: https://www.tumblr.com/vitalmobality/740949560387633152?source=share | H21: Live
B22: 2 | C22: https://www.4shared.com/ | D22: seo@thespeedtrain.com | E22: pooyaseo@thespeedtrain | F22: https://www.vitalmobility.ca/ | G22: https://www.4shared.com/s/flMlRJo0Cfa | H22: Live
B23: 3 | C23: https://photos.google.com/ | D23: seo@thespeedtrain.com | E23: pooyaseo@thespeedtrain | F23: https://www.vitalmobility.ca/ | G23: https://photos.app.goo.gl/RTej94ZqSjCqJB4d7 | H23: Live

Sheet Infographic Promotion
B2: Infographic Submission
B3: Website - https://www.vitalmobility.ca/
B6: Sr.No | C6: Website | D6: Gmail | E6: Password | F6: Target URL | G6: Live URL | H6: Status
B7: 1 | C7: https://justpaste.it/ | D7: seo@thespeedtrain.com | E7: pooyaseo@thespeedtrain | F7: https://www.vitalmobility.ca/ | G7: https://jpst.it/3zpeY | H7: Live
B8: 2 | C8: https://www.tumblr.com | D8: seo@thespeedtrain.com | E8: pooyaseo@thespeedtrain | F8: https://www.vitalmobility.ca/ | G8: https://www.tumblr.com/vitalmobality/741044396498272256/vital-mobility-medical-equipment-toronto?source=share | H8: Live
B9: 3 | C9: https://www.pearltrees.com | D9: seo@thespeedtrain.com | E9: pooyaseo@thespeedtrain | F9: https://www.vitalmobility.ca/ | G9: https://www.pearltrees.com/vitalmoility | H9: Live
B10: 4 | C10: https://www.scribd.com | D10: seo@thespeedtrain.com | E10: pooyaseo@thespeedtrain | F10: https://www.vitalmobility.ca/ | G10: https://www.scribd.com/document/702727975/Blue-and-White-Home-based-Health-Service-Instagram-Post-1 | H10: Live
B12: Sr.No | C12: Website | D12: Gmail | E12: Password | F12: Target URL | G12: Live URL | H12: Status
B13: 1 | C13: https://wakelet.com | D13: seo@thespeedtrain.com | E13: pooyaseo@thespeedtrain | F13: https://www.vitalmobility.ca/ | G13: https://wakelet.com/wake/n2JuUciEJb21-Dx7oZTsR | H13: Live
B14: 2 | C14: https://www.diigo.com | D14: seo@thespeedtrain.com | E14: pooyaseo@thespeedtrain | F14: https://www.vitalmobility.ca/ | G14: https://www.diigo.com/user/vitalmoblity | H14: Live
B15: 3 | C15: https://imgbb.com/ | D15: seo@thespeedtrain.com | E15: pooyaseo@thespeedtrain | F15: https://www.vitalmobility.ca/ | G15: https://vitalmobility.imgbb.com/ | H15: Live
B16: 4 | C16: https://500px.com/ | D16: seo@thespeedtrain.com | E16: pooyaseo@thespeedtrain | F16: https://www.vitalmobility.ca/ | G16: https://500px.com/photo/1084798718/blue-and-white-home-based-health-service-instagram-post-1-by-vital-mobility | H16: Live

Sheet PDF Submission
B2: PDF Submission
B3: Website - https://www.vitalmobility.ca/
B6: Sr.No | C6: Website | D6: Gmail | E6: Password | F6: Target URL | G6: Live URL | H6: Status
B7: 1 | C7: https://www.4shared.com/ | D7: seo@thespeedtrain.com | E7: vital321 | F7: https://www.vitalmobility.ca/electric-hospital-bed.php | G7: https://www.4shared.com/s/fNk3PmP3gge | H7: Live
B8: 2 | C8: https://files.fm/ | D8: seo@thespeedtrain.com | E8: vital321 | F8: https://www.vitalmobility.ca/electric-hospital-bed.php | G8: https://files.fm/u/kr8kvkn4rk | H8: Live
B9: 3 | C9: https://www.diigo.com/ | D9: seo@thespeedtrain.com | E9: vital321 | F9: https://www.vitalmobility.ca/electric-hospital-bed.php | G9: https://diigo.com/0v9u2q | H9: Live
B12: Sr.No | C12: Website | D12: Gmail | E12: Password | F12: Target URL | G12: Live URL | H12: Status
B13: 1 | C13: https://www.slideserve.com/ | D13: seo@thespeedtrain.com | E13: vital321 | F13: https://www.vitalmobility.ca/electric-hospital-bed.php | G13: https://www.slideserve.com/Seo517/blue-illustration-medical-service-flyer | H13: Live
B14: 2 | C14: https://issuu.com/ | D14: seo@thespeedtrain.com | E14: vital321 | F14: https://www.vitalmobility.ca/electric-hospital-bed.php | G14: https://issuu.com/vitalmobility1/docs/blue_illustration_medical_service_flyer | H14: Live
B15: 3 | C15: https://houseremovalists22.dropmark.com/ | D15: seo@thespeedtrain.com | E15: vital321 | F15: https://www.vitalmobility.ca/electric-hospital-bed.php | G15: https://vitalmobility1.dropmark.com/1638291 | H15: Live

Sheet PDF Promotion
B2: PDF Promotion
B3: Website - https://www.vitalmobility.ca/
B6: Sr.No | C6: Website | D6: Gmail | E6: Password | F6: Target URL | G6: Live URL | H6: Status
